<mujoco model="alex_v1_full_body">
    <compiler angle="radian" eulerseq="XYZ" meshdir="." autolimits="true" balanceinertia="true"/>

    <!-- <option iterations="3" ls_iterations="5" timestep="0.002" integrator="Euler">
        <flag eulerdamp="disable"/>
    </option> -->

    <default>
        <default class="alex">
            <joint damping="2" frictionloss="0.3"/>
            <position inheritrange="2"/>
            <default class="alex/spine">
                <joint axis="0 0 1" range="-0.5235987756 0.5235987756"/>
                <position forcerange="-450 450" kp="560"/>
            </default>
            <default class="alex/hip">
                <default class="alex/hip/x">
                    <joint axis="1 0 0" armature="0.004085"/>
                    <position forcerange="-450 450" kp="560"/>
                    <default class="alex/hip/x/left">
                        <joint range="-0.3490658504 0.872664626"/>
                    </default>
                    <default class="alex/hip/x/right">
                        <joint range="-0.872664626 0.3490658504"/>
                    </default>
                </default>
                <default class="alex/hip/y">
                    <joint axis="0 1 0" range="-2.61799 0.785398" armature="0.01026"/>
                    <position forcerange="-600 600" kp="750"/>
                </default>
                <default class="alex/hip/z">
                    <joint axis="0 0 1" armature="0.00124"/>
                    <position forcerange="-180 180" kp="225"/>
                    <default class="alex/hip/z/left">
                        <joint range="-0.3490658504 1.0472"/>
                    </default>
                    <default class="alex/hip/z/right">
                        <joint range="-1.0472 0.3490658504"/>
                    </default>
                </default>
            </default>
            <default class="alex/knee">
                <joint axis="0 1 0" range="0.0 2.445206282" armature="0.01026"/>
                <position forcerange="-600 600" kp="750"/>
            </default>
            <default class="alex/ankle">
                <joint armature="0.002301"/>
                <default class="alex/ankle/x">
                    <joint axis="1 0 0" range="-1.0472 0.523599"/>
                    <position forcerange="-270 270" kp="335"/>
                </default>
                <default class="alex/ankle/y">
                    <joint axis="0 1 0" range="-0.436332 0.436332"/>
                    <position forcerange="-540 540" kp="675"/>
                </default>
            </default>
            <default class="alex/shoulder">
                <default class="alex/shoulder/y">
                    <joint axis="0 1 0" range="-3.141592 1.22173" armature="0.01"/>
                    <position forcerange="-450 450" kp="562"/>
                </default>
                <default class="alex/shoulder/x">
                    <joint axis="1 0 0" armature="0.01"/>
                    <position forcerange="-300 300" kp="375"/>
                    <default class="alex/shoulder/x/left">
                        <joint range="-0.349066 2.79253"/>
                    </default>
                    <default class="alex/shoulder/x/right">
                        <joint range="-2.79253 0.349066"/>
                    </default>
                </default>
                <default class="alex/shoulder/z">
                    <joint axis="0 0 1" armature="0.01"/>
                    <position forcerange="-240 240" kp="300"/>
                    <default class="alex/shoulder/z/left">
                        <joint range="-1.91986 1.22173"/>
                    </default>
                    <default class="alex/shoulder/z/right">
                        <joint range="-1.22173 1.91986"/>
                    </default>
                </default>
            </default>
            <default class="alex/elbow">
                <joint axis="0 1 0" range="-2.35619 0.174532925" armature="0.01"/>
                <position forcerange="-240 240" kp="300"/>
            </default>
            <default class="alex/wrist">
                <position forcerange="-60 60" kp="75"/>
                <default class="alex/wrist/z">
                    <joint axis="0 0 1" range="-2.61799 2.61799" armature="0.01"/>
                </default>
                <default class="alex/wrist/x">
                    <joint axis="1 0 0" armature="0.01"/>
                    <default class="alex/wrist/x/left">
                        <joint range="-1.8326 0.610865"/>
                    </default>
                    <default class="alex/wrist/x/right">
                        <joint range="-0.610865 1.8326"/>
                    </default>
                </default>
            </default>
            <default class="alex/neck">
                <position forcerange="-60 60" kp="75"/>
                <default class="alex/neck/z">
                    <joint axis="0 0 1" range="-1.5708 1.5708" armature="0.01"/>
                </default>
                <default class="alex/neck/y">
                    <joint axis="0 1 0" range="-1.0472 1.0472" armature="0.01"/>
                </default>
            </default>
            <default class="alex/imu">
                <site group="4" rgba="0 0 1 0.4"/>
                <default class="alex/imu/pelvis">
                    <site pos="-0.08687724 0.01225028 -0.08051472"/>
                </default>
                <default class="alex/imu/hip">
                    <default class="alex/imu/hip/left">
                        <site pos="-0.01922309 0.10145013 -0.01488788" euler="-1.570796 0 1.570796"/>
                    </default>
                    <default class="alex/imu/hip/right">
                        <site pos="-0.01922309 -0.07694987 -0.01488788" euler="-1.570796 0 1.570796"/>
                    </default>
                </default>
                <default class="alex/imu/thigh">
                    <default class="alex/imu/thigh/left">
                        <site pos="0.10004 0.03746 -0.21194" euler="1.6947717585 0 1.570796"/>
                    </default>
                    <default class="alex/imu/thigh/right">
                        <site pos="0.10003618 -0.033541826 -0.21194191" euler="1.6947717585 0 1.570796"/>
                    </default>
                </default>
                <default class="alex/imu/shin">
                    <default class="alex/imu/shin/left">
                        <site pos="0.05655120 0.00084826 -0.15664831" euler="1.403695170631842 0 -1.570796"/>
                    </default>
                    <default class="alex/imu/shin/right">
                        <site pos="0.05673025 -0.00875818 -0.15674961" euler="1.403695170631842 0 -1.570796"/>
                    </default>
                </default>
                <default class="alex/imu/foot">
                    <site pos="-0.03575526 0.01180178 -0.04979705"/>
                </default>
                <default class="alex/imu/torso">
                    <site pos="0.04529 -0.02427 0.33757" euler="3.141592 0 0"/>
                </default>
                <default class="alex/imu/head">
                    <site pos="0.040556 -0.014155 0.057016" euler="0.56723 0.0 1.5708"/>
                </default>
                <default class="alex/imu/shoulder_y">
                    <default class="alex/imu/shoulder_y/left">
                        <site pos="0.0174 0.06944 -0.03025" euler="-1.570796 1.570796 0"/>
                    </default>
                    <default class="alex/imu/shoulder_y/right">
                        <site pos="0.0175 -0.0704 -0.00778" euler="1.570796 -1.570796 0"/>
                    </default>
                </default>
                <default class="alex/imu/shoulder_z">
                    <default class="alex/imu/shoulder_z/left">
                        <site pos="-0.00763459 -0.0123324 -0.318" euler="-1.570796 3.1415926 -0.314159"/>
                    </default>
                    <default class="alex/imu/shoulder_z/right">
                        <site pos="0.002 0.016 -0.318" euler="1.570796 0 0.314159"/>
                    </default>
                </default>
                <default class="alex/imu/wrist_z">
                    <default class="alex/imu/wrist_z/left">
                        <site pos="-0.033554 0.010450 -0.148527" euler="1.571 0.0 1.571"/>
                    </default>
                    <default class="alex/imu/wrist_z/right">
                        <site pos="-0.033554 0.010450 -0.148527" euler="1.571 0.0 1.571"/>
                    </default>
                </default>
                <default class="alex/imu/gripper_z">
                    <default class="alex/imu/gripper_z/left">
                        <site pos="0 0 0" euler="0 0 0"/>
                    </default>
                    <default class="alex/imu/gripper_z/right">
                        <site pos="0 0 0" euler="0 0 0"/>
                    </default>
                </default>
            </default>
            <default class="alex/visual">
                <geom contype="0" conaffinity="0" type="mesh"/>
            </default>
            <default class="alex/collision">
                <geom group="3" contype="1" conaffinity="1" rgba="0 1 0 0.4"/>
                <default class="alex/collision/thigh">
                    <geom type="capsule" euler="0 -0.25 0" size="0.095 0.11" condim="1" friction="0.8"/>
                </default>
                <default class="alex/collision/foot">
                    <geom type="box" size="0.0985 0.045 0.01" pos="0.045 0.0 -0.0625" condim="6" friction="1.0 0.1 0.01" solref="0.01 1" solimp="0.9 0.99 0.003"/>
                </default>
                <default class="alex/collision/pelvis">
                    <geom type="box" size="0.12 0.10 0.07" pos="-0.06 0.0 -0.03" condim="3" friction="0.9 0.05 0.01" solref="0.015 1" solimp="0.9 0.99 0.003"/>
                </default>
                <default class="alex/collision/torso">
                    <geom type="capsule" fromto="-0.02 0.0 0.02 -0.02 0.0 0.47" size="0.10" condim="3" friction="0.9 0.05 0.01" solref="0.015 1" solimp="0.9 0.99 0.003"/>
                </default>
                <default class="alex/collision/shin">
                    <geom type="capsule" fromto="0.02 0.0 -0.02 0.06 0.0 -0.30" size="0.06" condim="3" friction="0.9 0.05 0.01" solref="0.015 1" solimp="0.9 0.99 0.003"/>
                </default>
                <default class="alex/collision/upper_arm">
                    <geom type="capsule" fromto="0 0 0 0.015 0 -0.30" size="0.055" condim="3" friction="0.8 0.04 0.01" solref="0.015 1" solimp="0.9 0.99 0.003"/>
                </default>
                <default class="alex/collision/forearm">
                    <geom type="capsule" fromto="0 0 -0.02 0 -0.013 -0.23" size="0.045" condim="3" friction="0.8 0.04 0.01" solref="0.015 1" solimp="0.9 0.99 0.003"/>
                </default>
                <default class="alex/collision/head">
                    <geom type="sphere" size="0.10" pos="0.04 0.0 0.02" condim="3" friction="0.8 0.04 0.01" solref="0.015 1" solimp="0.9 0.99 0.003"/>
                </default>
            </default>
        </default>
    </default>

    <asset>
        <material name="metal" rgba=".9 .95 .95 1"/>
        <material name="black" rgba="0 0 0 1"/>
        <material name="white" rgba="1 1 1 1"/>
        <material name="gray" rgba="0.671705 0.692426 0.774270 1"/>
        <mesh name="left_ankle" file="../meshes/legs/AnklePitchLink.obj"/>
        <mesh name="left_foot" file="../meshes/legs/Foot.obj"/>
        <mesh name="left_hip_x" file="../meshes/legs/LeftHipRollLink.obj"/>
        <mesh name="left_hip_z" file="../meshes/legs/LeftHipYawLink.obj"/>
        <mesh name="left_shin" file="../meshes/legs/LeftShin.obj"/>
        <mesh name="left_thigh" file="../meshes/legs/LeftThigh.obj"/>
        <mesh name="pelvis" file="../meshes/legs/Pelvis.obj"/>
        <mesh name="right_ankle" file="../meshes/legs/AnklePitchLink.obj"/>
        <mesh name="right_foot" file="../meshes/legs/Foot.obj"/>
        <mesh name="right_hip_x" file="../meshes/legs/RightHipRollLink.obj"/>
        <mesh name="right_hip_z" file="../meshes/legs/RightHipYawLink.obj"/>
        <mesh name="right_shin" file="../meshes/legs/RightShin.obj"/>
        <mesh name="right_thigh" file="../meshes/legs/RightThigh.obj"/>
        <mesh name="head" file="../meshes/ALX02_01_A02_HeadLink.obj"/>
        <mesh name="torso" file="../meshes/torso.obj"/>
        <mesh name="left_shoulder_y" file="../meshes/cycloidal_arm/LeftShoulderPitchLink.obj"/>
        <mesh name="left_shoulder_x" file="../meshes/cycloidal_arm/LeftShoulderRollLink_shortBicep.obj"/>
        <mesh name="left_shoulder_z" file="../meshes/cycloidal_arm/LeftShoulderYawLink.obj"/>
        <mesh name="left_elbow_y" file="../meshes/cycloidal_arm/LeftElbowPitchLink.obj"/>
        <mesh name="left_wrist_z" file="../meshes/cycloidal_arm/LeftWristYawLink.obj"/>
        <mesh name="left_wrist_x" file="../meshes/cycloidal_arm/LeftWristRollLink.obj"/>
        <mesh name="left_gripper" file="../meshes/cycloidal_arm/nub.obj" inertia="convex"/>
        <mesh name="right_shoulder_y" file="../meshes/cycloidal_arm/RightShoulderPitchLink.obj"/>
        <mesh name="right_shoulder_x" file="../meshes/cycloidal_arm/RightShoulderRollLink_shortBicep.obj"/>
        <mesh name="right_shoulder_z" file="../meshes/cycloidal_arm/RightShoulderYawLink.obj"/>
        <mesh name="right_elbow_y" file="../meshes/cycloidal_arm/RightElbowPitchLink.obj"/>
        <mesh name="right_wrist_z" file="../meshes/cycloidal_arm/RightWristYawLink.obj"/>
        <mesh name="right_wrist_x" file="../meshes/cycloidal_arm/RightWristRollLink.obj"/>
        <mesh name="right_gripper" file="../meshes/cycloidal_arm/nub.obj" inertia="convex"/>
    </asset>

    <worldbody>
         <body name="pelvis_link" pos="0.0 0.0 1.0" childclass="alex">
            <inertial 
                pos="-0.08256965 0.00003644 -0.03242784"
                mass="7.161"
                fullinertia="0.02977256988 0.03911256674 0.04671200364 0.00000354246 0.00058151866 0.00002715104"
                />
            <freejoint/>
            <geom mesh="pelvis" material="gray" class="alex/visual"/>
            <geom name="pelvis_collision" class="alex/collision/pelvis"/>
            <site name="imu_pelvis" class="alex/imu/pelvis"/>
            <body name="left_hip_x" pos="-0.162 0.0595 -0.015">
                <inertial 
                    pos="0.04350911	0.08708606 -0.03525761"
                    mass="2.332078"
                    fullinertia="0.00469288 0.00517742 0.00554081 -0.00059599 0.00013313 0.00048434"
                    />
                <joint name="left_hip_x" class="alex/hip/x/left"/>
                <geom mesh="left_hip_x" material="gray" class="alex/visual"/>
                <site name="imu_left_hip" class="alex/imu/hip/left"/>
                <body name="left_hip_z" pos="0.06	0.1	-0.08">
                    <inertial 
                        pos="0.04549595	-0.00525571	-0.00937454"
                        mass="0.74972192"
                        fullinertia="0.00301724 0.00328402 0.00292463 -0.00015575 0.00074098 -0.00040842"
                        />
                    <joint name="left_hip_z" class="alex/hip/z/left"/>
                    <geom mesh="left_hip_z" material="gray" class="alex/visual"/>
                    <body name="left_thigh" pos="0.1045	-0.0573	-0.0525">
                        <inertial 
                            pos="0.01417302 0.03268781 -0.10548314"
                            mass="8.286"
                            fullinertia="0.09293216 0.09767341 0.02812998 0.00035382 0.00924622 -0.0043387"
                            />
                        <joint name="left_hip_y" class="alex/hip/y"/>
                        <geom mesh="left_thigh" material="gray" class="alex/visual"/>
                        <geom name="left_thigh_collision" pos="0.015 0.025 -0.125" class="alex/collision/thigh"/>
                        <site name="imu_left_thigh" class="alex/imu/thigh/left"/>
                        <body name="left_shin" pos="0 0.018 -0.32">
                            <inertial 
                                pos="0.03807965	-0.00108105	-0.12410027"
                                mass="6.3405718"
                                fullinertia="0.08822008 0.091628 0.01569249 -0.00053613 -0.00634659 0.00004183"
                                />
                            <joint name="left_knee_y" class="alex/knee"/>
                            <geom mesh="left_shin" material="gray" class="alex/visual"/>
                            <geom name="left_shin_collision" class="alex/collision/shin"/>
                            <site name="imu_left_shin" class="alex/imu/shin/left"/>
                            <body name="left_ankle" pos="0 0 -0.41">
                                <inertial 
                                    pos="2.94E-07 2.22E-07 -0.00462997"
                                    mass="0.05045632"
                                    fullinertia="2.12239132463e-05 1.17836327346e-06 7.91376398006e-06 4.99870769421e-06 1.29588542506e-05 3.05224469886e-06"
                                    />
                                <joint name="left_ankle_y" class="alex/ankle/y"/>
                                <geom mesh="left_ankle" material="gray" class="alex/visual"/>
                                <body name="left_foot" pos="0 0 -0.012">
                                    <inertial 
                                        pos="0.03793372	-0.00000219	-0.0443663"
                                        mass="1.28831268"
                                        fullinertia="0.0013169 0.00385838 0.00406674 0.00001054 0.00036437 -0.00000573"
                                        />
                                    <joint name="left_ankle_x" class="alex/ankle/x"/>
                                    <geom mesh="left_foot" material="gray" class="alex/visual"/>
                                    <geom name="left_foot_collision" class="alex/collision/foot"/>
                                    <site name="imu_left_foot" class="alex/imu/foot"/>
                                    <site name="left_foot_site"/>
                                </body>
                            </body>
                        </body>
                    </body>
                </body>
            </body>
            <body name="right_hip_x" pos="-0.162	-0.0595	-0.015">
                <inertial 
                    pos="0.04351957	-0.08688935	-0.03525357"
                    mass="2.33123426"
                    fullinertia="0.00468506 0.00517303 0.00553045 0.00061027 0.0001309 -0.00047425"/>
                <joint name="right_hip_x" class="alex/hip/x/right"/>
                <geom mesh="right_hip_x" material="gray" class="alex/visual"/>
                <site name="imu_right_hip" class="alex/imu/hip/right"/>
                <body name="right_hip_z" pos="0.06 -0.1 -0.08">
                    <inertial 
                        pos="0.04549274 0.00525784 -0.00937505"
                        mass="0.77280715"
                        fullinertia="0.00317639 0.0034518 0.00313243 0.00005807 0.00080598 0.00047441"
                        />
                    <joint name="right_hip_z" class="alex/hip/z/right"/>
                    <geom mesh="right_hip_z" material="gray" class="alex/visual"/>
                    <body name="right_thigh" pos="0.1045 0.0573 -0.0525">
                        <inertial 
                            pos="0.01411846 -0.03282392 -0.10542795"
                            mass="8.27617423"
                            fullinertia="0.09281503 0.09743827 0.02800443 -0.00024328 0.00917054 0.00423839"
                            />
                        <joint name="right_hip_y" class="alex/hip/y"/>
                        <geom mesh="right_thigh" material="gray" class="alex/visual"/>
                        <geom name="right_thigh_collision" pos="0.015 -0.025 -0.125" class="alex/collision/thigh"/>
                        <site name="imu_right_thigh" class="alex/imu/thigh/right"/>
                        <body name="right_shin" pos="0 -0.018 -0.32">
                            <inertial 
                                pos="0.03807648	0.00113375 -0.12408765"
                                mass="6.33633928"
                                fullinertia="0.08730216 0.090578 0.01566017 0.00053892 -0.0066006 0.00029428"
                                />
                            <joint name="right_knee_y" class="alex/knee"/>
                            <geom mesh="right_shin" material="gray" class="alex/visual"/>
                            <geom name="right_shin_collision" class="alex/collision/shin"/>
                            <site name="imu_right_shin" class="alex/imu/shin/right"/>
                            <body name="right_ankle" pos="0 0 -0.41">
                                <inertial 
                                    pos="2.94E-07 2.22E-07 -0.00462997"
                                    mass="0.05045632"
                                    fullinertia="2.12239132463e-05 1.17836327346e-06 7.91376398006e-06 4.99870769421e-06 1.29588542506e-05 3.05224469886e-06"
                                    />
                                <joint name="right_ankle_y" class="alex/ankle/y"/>
                                <geom mesh="right_ankle" material="gray" class="alex/visual"/>
                                <body name="right_foot" pos="0 0 -0.012">
                                    <inertial 
                                        pos="0.03793372	-0.00000219	-0.0443663"
                                        mass="1.28831268"
                                        fullinertia="0.0013169 0.00385838 0.00406674 0.00001054 0.00036437 -0.00000573"
                                        />
                                    <joint name="right_ankle_x" class="alex/ankle/x"/>
                                    <geom mesh="right_foot" material="gray" class="alex/visual"/>
                                    <geom name="right_foot_collision" class="alex/collision/foot"/>
                                    <site name="imu_right_foot" class="alex/imu/foot"/>
                                    <site name="right_foot_site"/>
                                </body>
                            </body>
                        </body>
                    </body>
                </body>
            </body>
            <body name="torso" pos="0.0 0 0.018">
                <inertial 
                    pos="-0.014 0.001 0.326"
                    mass="11.478322779"
                    fullinertia="0.1764967124 0.1237602 0.1109598365 0.00002329659 0.00830355822 0.00072436338"
                    />
                <joint name="spine_z" class="alex/spine"/>
                <geom mesh="torso" pos="0.0 0.0 0.105063" material="gray" class="alex/visual"/>
                <geom name="torso_collision" class="alex/collision/torso"/>
                <site name="imu_torso" class="alex/imu/torso"/>
                <body name="left_shoulder_y" pos="-0.015 0.115474 0.352984" euler="0.698132 0.0 0.0">
                    <inertial 
                        pos="-0.00264 0.12135 -0.006824"
                        mass="3.0331992"
                        fullinertia="0.01114656 0.00699715 0.0099942 0.00024166 0.0001507 0.00308767"
                        />
                    <joint name="left_shoulder_y" class="alex/shoulder/y"/>
                    <geom mesh="left_shoulder_y" material="gray" class="alex/visual"/>
                    <site name="imu_left_shoulder_y" class="alex/imu/shoulder_y/left"/>
                    <body name="left_shoulder_x" pos="0.0 0.15676000 -0.01300000" euler="-0.698132 0.0 0.0">
                        <inertial 
                            pos="0.01053 0.02124 -0.1052690"
                            mass="1.16160776"
                            fullinertia="0.00786831 0.00727049 0.0018045 0.00016417 -0.00075696 0.00099239"
                            />
                        <joint name="left_shoulder_x" class="alex/shoulder/x/left"/>
                        <geom mesh="left_shoulder_x" material="gray" class="alex/visual"/>
                        <body name="left_shoulder_z" pos="0.0 0.035 0.0" euler="0.0 0.0 0.0">
                            <inertial 
                                pos="0.00510403 0.00274 -0.21745"
                                mass="3.134"
                                fullinertia="0.02661157 0.02633278 0.00308445 0.00000297 0.00147256 0.00039997"
                                />
                            <joint name="left_shoulder_z" class="alex/shoulder/z/left"/>
                            <geom mesh="left_shoulder_z" pos="0.0 0.0 0.0867" material="gray" class="alex/visual"/>
                            <geom name="left_upper_arm_collision" class="alex/collision/upper_arm"/>
                            <site name="imu_left_shoulder_z" class="alex/imu/shoulder_z/left"/>
                            <body name="left_elbow_y" pos="0.015 0.0 -0.3127" euler="0.0 0.0 0.0">
                                <inertial 
                                    pos="-0.01180322 -0.0035763 -0.04946747"
                                    mass="0.45"
                                    fullinertia="0.000890273241784 0.000262527800896 0.000245493270197 0.000452238869537 0.000368339524424 0.00013185002882"
                                    />
                                <joint name="left_elbow_y" class="alex/elbow"/>
                                <geom mesh="left_elbow_y" material="gray" class="alex/visual"/>
                                <body name="left_wrist_z" pos="-0.015 0.0 0.0" euler="0.0 0.0 0.0">
                                    <inertial 
                                        pos="-0.00263832 -0.00050534 -0.13018376"
                                        mass="1.547"
                                        fullinertia="0.00464271728288 0.00175435235119 0.00023266084023 0.00285393685706 0.00103931401829 0.000638879570088"
                                        />
                                    <joint name="left_wrist_z" class="alex/wrist/z"/>
                                    <geom mesh="left_wrist_z" material="gray" class="alex/visual"/>
                                    <geom name="left_forearm_collision" class="alex/collision/forearm"/>
                                    <site name="imu_left_wrist_z" class="alex/imu/wrist_z/left"/>
                                    <body name="left_wrist_x" pos="0.0 -0.013 -0.25" euler="0.0 0.0 0.0">
                                        <inertial 
                                            pos="0.00004053 0.01038395 0.00035532"
                                            mass="0.909"
                                            fullinertia="0.000652053013072 0.000159003865637 0.000177185453439 0.000319270117963 0.000337486856275 0.000162655621336"
                                            />
                                        <joint name="left_wrist_x" class="alex/wrist/x/left"/>
                                        <geom mesh="left_wrist_x" material="gray" class="alex/visual"/>
                                        <body name="left_gripper" pos="0.0 0.013 -0.031" euler="0.0 0.0 0.0">
                                            <inertial 
                                                pos="-0.000217 -0.000349 0.009761"
                                                mass="0.251"
                                                fullinertia="8.82672027084e-05 3.09484319687e-05 7.61072854977e-06 5.18316320154e-05 2.16363464714e-05 1.1619853382e-05"
                                                />
                                            <geom mesh="left_gripper" quat="0.707 0.0 0.707 0.0" material="gray" class="alex/visual"/>
                                        </body>
                                    </body>
                                </body>
                            </body>
                        </body>
                    </body>
                </body>
                <body name="neck_z" pos="-0.015 0 0.450403" euler="0.0 0.0 0.0">
                    <inertial 
                        pos="0.00626571 0.0059834 0.15148116"
                        mass="1.03172573"
                        fullinertia="0.00611354 0.00602503 0.0009799 -0.00005224 -0.00058532 -0.00028073"
                        />
                    <joint name="neck_z" class="alex/neck/z"/>
                    <geom type="cylinder" size="0.05 0.05" material="gray" class="alex/visual"/>
                    <body name="head" pos="0.025 0.01 0.189597" euler="0.0 0.0 0.0">
                        <inertial 
                            pos="0.0407664 -0.00396678 0.007163"
                            mass="1.27065932"
                            fullinertia="0.00424227 0.00501825 0.00451978 -0.00008839 0.00054485 -0.00010863"
                            />
                        <joint name="neck_y" class="alex/neck/y"/>
                        <geom mesh="head" material="gray" class="alex/visual"/>
                        <geom name="head_collision" class="alex/collision/head"/>
                        <site name="imu_head" class="alex/imu/head"/>
                    </body>
                </body>
                <body name="right_shoulder_y" pos="-0.015 -0.115474 0.352984" euler="-0.698132 0.0 0.0">
                    <inertial 
                        pos="-0.00264 -0.12135 -0.006824"
                        mass="3.00752318"
                        fullinertia="0.01107924 0.00695098 0.00991808 -0.00026479 -0.00015595 -0.00308767"
                        />
                    <joint name="right_shoulder_y" class="alex/shoulder/y"/>
                    <geom mesh="right_shoulder_y" material="gray" class="alex/visual"/>
                    <site name="imu_right_shoulder_y" class="alex/imu/shoulder_y/right"/>
                    <body name="right_shoulder_x" pos="0.0 -0.15676000 -0.01300000" euler="0.698132 0.0 0.0">
                        <inertial 
                            pos="0.01053 -0.02124 -0.1052690"
                            mass="1.1615873"
                            fullinertia="0.00786905 0.00727111 0.00180465 -0.00016408 -0.00075601 -0.00099114"
                            />
                        <joint name="right_shoulder_x" class="alex/shoulder/x/right"/>
                        <geom mesh="right_shoulder_x" material="gray" class="alex/visual"/>
                        <body name="right_shoulder_z" pos="0.0 -0.035 0.0" euler="0.0 0.0 0.0">
                            <inertial 
                                pos="0.00524 -0.00274 -0.21745"
                                mass="3.10111287"
                                fullinertia="0.0262817 0.02606342 0.00304834 0.00000996 0.0015423 -0.0004047"
                                />
                            <joint name="right_shoulder_z" class="alex/shoulder/z/right"/>
                            <geom mesh="right_shoulder_z" pos="0.0 0.0 0.0867" material="gray" class="alex/visual"/>
                            <geom name="right_upper_arm_collision" class="alex/collision/upper_arm"/>
                            <site name="imu_right_shoulder_z" class="alex/imu/shoulder_z/right"/>
                            <body name="right_elbow_y" pos="0.015 0.0 -0.3127" euler="0.0 0.0 0.0">
                                <inertial 
                                    pos="-0.0127 0.006913 -0.048421"
                                    mass="0.45"
                                    fullinertia="0.000793896879259 0.000241167083575 7.26748524931e-05 0.00043756229267 0.000240198817699 0.000132387568843"
                                    />
                                <joint name="right_elbow_y" class="alex/elbow"/>
                                <geom mesh="right_elbow_y" material="gray" class="alex/visual"/>
                                <body name="right_wrist_z" pos="-0.015 0.0 0.0" euler="0.0 0.0 0.0">
                                    <inertial 
                                        pos="-0.002616 0.000462 -0.13019"
                                        mass="1.547"
                                        fullinertia="0.00463517542084 0.001746285842 0.000326962427525 0.00283604196999 0.00106507115374 0.000621527932295"
                                        />
                                    <joint name="right_wrist_z" class="alex/wrist/z"/>
                                    <geom mesh="right_wrist_z" material="gray" class="alex/visual"/>
                                    <geom name="right_forearm_collision" class="alex/collision/forearm"/>
                                    <site name="imu_right_wrist_z" class="alex/imu/wrist_z/right"/>
                                    <body name="right_wrist_x" pos="0.0 0.013 -0.25" euler="0.0 0.0 0.0">
                                        <inertial 
                                            pos="-0.0000481 -0.012143 0.000196"
                                            mass="0.909"
                                            fullinertia="0.000750844385968 0.000192455812265 0.00021120477793 0.000365160427359 0.000385723812908 0.000173662804958"
                                            />
                                        <joint name="right_wrist_x" class="alex/wrist/x/right"/>
                                        <geom mesh="right_wrist_x" material="gray" class="alex/visual"/>
                                        <body name="right_gripper" pos="0.0 -0.013 -0.031" euler="0.0 0.0 0.0">
                                            <inertial 
                                                pos="-0.000217 -0.000349 0.009761"
                                                mass="0.251"
                                                fullinertia="8.82672027084e-05 3.09484319687e-05 7.61072854977e-06 5.18316320154e-05 2.16363464714e-05 1.1619853382e-05"
                                                />
                                            <geom mesh="right_gripper" quat="0.707 0.0 0.707 0.0" material="gray" class="alex/visual"/>
                                        </body>
                                    </body>
                                </body>
                            </body>
                        </body>
                    </body>
                </body>
            </body>
        </body>
    </worldbody>

    <contact>
        <exclude body1="torso" body2="left_shoulder_y"/>
        <exclude body1="torso" body2="right_shoulder_y"/>
        <exclude body1="neck_z" body2="left_shoulder_y"/>
        <exclude body1="neck_z" body2="right_shoulder_y"/>
        <exclude body1="left_shoulder_y" body2="left_shoulder_x"/>
        <exclude body1="left_shoulder_x" body2="left_shoulder_z"/>
        <exclude body1="left_shoulder_z" body2="left_elbow_y"/>
        <exclude body1="left_elbow_y" body2="left_wrist_z"/>
        <exclude body1="left_wrist_z" body2="left_wrist_x"/>
        <exclude body1="left_wrist_x" body2="left_gripper"/>
        <exclude body1="right_shoulder_y" body2="right_shoulder_x"/>
        <exclude body1="right_shoulder_x" body2="right_shoulder_z"/>
        <exclude body1="right_shoulder_z" body2="right_elbow_y"/>
        <exclude body1="right_elbow_y" body2="right_wrist_z"/>
        <exclude body1="right_wrist_z" body2="right_wrist_x"/>
        <exclude body1="right_wrist_x" body2="right_gripper"/>
    </contact>

    <actuator>
        <!-- Legs -->
        <position name="left_hip_x"   joint="left_hip_x"   class="alex/hip/x"/>
        <position name="left_hip_z"   joint="left_hip_z"   class="alex/hip/z"/>
        <position name="left_hip_y"   joint="left_hip_y"   class="alex/hip/y"/>
        <position name="left_knee"    joint="left_knee_y"  class="alex/knee"/>
        <position name="left_ankle_y" joint="left_ankle_y" class="alex/ankle/y"/>
        <position name="left_ankle_x" joint="left_ankle_x" class="alex/ankle/x"/>
        <position name="right_hip_x"   joint="right_hip_x"   class="alex/hip/x"/>
        <position name="right_hip_z"   joint="right_hip_z"   class="alex/hip/z"/>
        <position name="right_hip_y"   joint="right_hip_y"   class="alex/hip/y"/>
        <position name="right_knee"    joint="right_knee_y"  class="alex/knee"/>
        <position name="right_ankle_y" joint="right_ankle_y" class="alex/ankle/y"/>
        <position name="right_ankle_x" joint="right_ankle_x" class="alex/ankle/x"/>
        <!-- Spine -->
        <position name="spine_z" joint="spine_z" class="alex/spine"/>
        <!-- Left arm -->
        <position name="left_shoulder_y" joint="left_shoulder_y" class="alex/shoulder/y"/>
        <position name="left_shoulder_x" joint="left_shoulder_x" class="alex/shoulder/x"/>
        <position name="left_shoulder_z" joint="left_shoulder_z" class="alex/shoulder/z"/>
        <position name="left_elbow"    joint="left_elbow_y"  class="alex/elbow"/>
        <position name="left_wrist_z"  joint="left_wrist_z"  class="alex/wrist/z"/>
        <position name="left_wrist_x"  joint="left_wrist_x"  class="alex/wrist/x"/>
        <!-- Neck / head -->
        <position name="neck_z" joint="neck_z" class="alex/neck/z"/>
        <position name="neck_y" joint="neck_y" class="alex/neck/y"/>
        <!-- Right arm -->
        <position name="right_shoulder_y" joint="right_shoulder_y" class="alex/shoulder/y"/>
        <position name="right_shoulder_x" joint="right_shoulder_x" class="alex/shoulder/x"/>
        <position name="right_shoulder_z" joint="right_shoulder_z" class="alex/shoulder/z"/>
        <position name="right_elbow"    joint="right_elbow_y"  class="alex/elbow"/>
        <position name="right_wrist_z"  joint="right_wrist_z"  class="alex/wrist/z"/>
        <position name="right_wrist_x"  joint="right_wrist_x"  class="alex/wrist/x"/>
    </actuator>

    <sensor>
        <!-- Pelvis IMU: -->
         <gyro name="imu_pelvis_gyro" site="imu_pelvis"/>
         <accelerometer name="imu_pelvis_accelerometer" site="imu_pelvis"/>

        <!-- Left Hip IMU: -->
         <gyro name="imu_left_hip_gyro" site="imu_left_hip"/>
         <accelerometer name="imu_left_hip_accelerometer" site="imu_left_hip"/>

         <!-- Left Thight IMU: -->
        <gyro name="imu_left_thigh_gyro" site="imu_left_thigh"/>
        <accelerometer name="imu_left_thigh_accelerometer" site="imu_left_thigh"/>

        <!-- Left Shin IMU: -->
        <gyro name="imu_left_shin_gyro" site="imu_left_shin"/>
        <accelerometer name="imu_left_shin_accelerometer" site="imu_left_shin"/>

        <!-- Left Foot IMU: -->
        <gyro name="imu_left_foot_gyro" site="imu_left_foot"/>
        <accelerometer name="imu_left_foot_accelerometer" site="imu_left_foot"/>

        <!-- Right Hip IMU: -->
         <gyro name="imu_right_hip_gyro" site="imu_right_hip"/>
         <accelerometer name="imu_right_hip_accelerometer" site="imu_right_hip"/>

         <!-- Right Thight IMU: -->
        <gyro name="imu_right_thigh_gyro" site="imu_right_thigh"/>
        <accelerometer name="imu_right_thigh_accelerometer" site="imu_right_thigh"/>

        <!-- Right Shin IMU: -->
        <gyro name="imu_right_shin_gyro" site="imu_right_shin"/>
        <accelerometer name="imu_right_shin_accelerometer" site="imu_right_shin"/>

        <!-- Right Foot IMU: -->
        <gyro name="imu_right_foot_gyro" site="imu_right_foot"/>
        <accelerometer name="imu_right_foot_accelerometer" site="imu_right_foot"/>

        <!-- Torso IMU: -->
        <gyro name="imu_torso_gyro" site="imu_torso"/>
        <accelerometer name="imu_torso_accelerometer" site="imu_torso"/>

        <!-- Head IMU: -->
        <gyro name="imu_head_gyro" site="imu_head"/>
        <accelerometer name="imu_head_accelerometer" site="imu_head"/>

        <!-- Left Shoulder Pitch IMU: -->
        <gyro name="imu_left_shoulder_y_gyro" site="imu_left_shoulder_y"/>
        <accelerometer name="imu_left_shoulder_y_accelerometer" site="imu_left_shoulder_y"/>

        <!-- Left Shoulder Yaw IMU: -->
        <gyro name="imu_left_shoulder_z_gyro" site="imu_left_shoulder_z"/>
        <accelerometer name="imu_left_shoulder_z_accelerometer" site="imu_left_shoulder_z"/>

        <!-- Left Wrist Yaw IMU: -->
        <gyro name="imu_left_wrist_z_gyro" site="imu_left_wrist_z"/>
        <accelerometer name="imu_left_wrist_z_accelerometer" site="imu_left_wrist_z"/>
        
        <!-- Right Shoulder Pitch IMU: -->
        <gyro name="imu_right_shoulder_y_gyro" site="imu_right_shoulder_y"/>
        <accelerometer name="imu_right_shoulder_y_accelerometer" site="imu_right_shoulder_y"/>

        <!-- Right Shoulder Yaw IMU: -->
        <gyro name="imu_right_shoulder_z_gyro" site="imu_right_shoulder_z"/>
        <accelerometer name="imu_right_shoulder_z_accelerometer" site="imu_right_shoulder_z"/>

        <!-- Right Wrist Yaw IMU: -->
        <gyro name="imu_right_wrist_z_gyro" site="imu_right_wrist_z"/>
        <accelerometer name="imu_right_wrist_z_accelerometer" site="imu_right_wrist_z"/>

        <!-- Additional Sensors for training: -->
        <!-- Pelvis IMU: -->
        <framequat name="imu_pelvis_orientation" objtype="site" objname="imu_pelvis"/>
        <velocimeter name="imu_pelvis_linear_velocity" site="imu_pelvis"/>
        <framepos name="imu_pelvis_position" objtype="site" objname="imu_pelvis"/>

        <!-- Globals: -->
        <framezaxis name="upvector" objtype="site" objname="imu_pelvis"/>
        <framexaxis name="forwardvector" objtype="site" objname="imu_pelvis"/>
        <framelinvel name="global_linear_velocity" objtype="site" objname="imu_pelvis"/>
        <frameangvel name="global_angular_velocity" objtype="site" objname="imu_pelvis"/>
        <framelinvel name="left_foot_global_linear_velocity" objtype="site" objname="left_foot_site"/>
        <framelinvel name="right_foot_global_linear_velocity" objtype="site" objname="right_foot_site"/>
    </sensor>

</mujoco>
